<?xml version="1.0"?>
<!--小车底盘-->
<robot name="mbot">
    <link name="base_link">
        <visual>
            <origin xyz="0 0 0" rpy="0 0 0"/><!--起始位置坐标-->
            <geometry>
                <cylinder length="0.16" radius="0.20"/><!--底盘形状描述-->
            </geometry>
            <material name="yellow"><!--底盘材料-->
                <color rgba="1 0.4 0 1"/><!--底盘颜色-->
            </material>
        </visual>
    </link>
<!--小车左轮关节-->
    <joint name="left_wheel_joint" type="continuous">
        <origin xyz="0 0.19 -0.05" rpy="0 0 0"/>
        <parent link="base_link"/>
        <child link="left_wheel_link"/>
        <axis xyz="0 1 0"/>
    </joint>
<!--小车左轮-->
    <link name="left_wheel_link">
        <visual>
            <origin xyz="0 0 0" rpy="1.5707 0 0" /><!--0 0 0-->
            <geometry>
                <cylinder radius="0.06" length = "0.025"/>
            </geometry>
            <material name="white">
                <color rgba="1 1 1 0.9"/>
            </material>
        </visual>
    </link>
<!--小车右轮关节-->
    <joint name="right_wheel_joint" type="continuous">
        <origin xyz="0 -0.19 -0.05" rpy="0 0 0"/>
        <parent link="base_link"/>
        <child link="right_wheel_link"/>
        <axis xyz="0 1 0"/>
    </joint>
<!--小车右轮-->
    <link name="right_wheel_link">
        <visual>
            <origin xyz="0 0 0" rpy="1.5707 0 0" /><!--0 0 0-->
            <geometry>
                <cylinder radius="0.06" length = "0.025"/>
            </geometry>
            <material name="white">
                <color rgba="1 1 1 0.9"/>
            </material>
        </visual>
    </link>
<!--前支撑轮关节-->
    <joint name="front_caster_joint" type="continuous">
        <origin xyz="0.18 0 -0.095" rpy="0 0 0"/>
        <parent link="base_link"/>
        <child link="front_caster_link"/>
        <axis xyz="0 1 0"/>
    </joint>
<!--前支撑轮-->
    <link name="front_caster_link">
        <visual>
            <origin xyz="0 0 0" rpy="0 0 0"/><!--0 0 0-->
            <geometry>
                <sphere radius="0.015" />
            </geometry>
            <material name="black">
                <color rgba="0 0 0 0.95"/>
            </material>
        </visual>
    </link>
<!--后支撑轮关节-->
    <joint name="back_caster_joint" type="continuous">
        <origin xyz="-0.18 0 -0.095" rpy="0 0 0"/>
        <parent link="base_link"/>
        <child link="back_caster_link"/>
        <axis xyz="0 1 0"/>
    </joint>
<!--后支撑轮-->
    <link name="back_caster_link">
        <visual>
            <origin xyz="0 0 0" rpy="0 0 0"/><!--0 0 0-->
            <geometry>
                <sphere radius="0.015" />
            </geometry>
            <material name="black">
                <color rgba="0 0 0 0.95"/>
            </material>
        </visual>
    </link>
</robot>
